<?xml version="1.0" ?>

<robot name="my_robot" 
    xmlns:xacro="https://www.ros.org/wiki/xacro">

    <material name="black">
        <color rgba="0.0 0.0 0.0 1.0"/>
    </material>
    <material name="blue">
        <color rgba="0.203125 0.23828125 0.28515625 1.0"/>
    </material>
    <material name="green">
        <color rgba="0.0 0.8 0.0 1.0"/>
    </material>
    <material name="grey">
        <color rgba="0.2 0.2 0.2 1.0"/>
    </material>
    <material name="orange">
        <color rgba="1.0 0.423529411765 0.0392156862745 1.0"/>
    </material>
    <material name="brown">
        <color rgba="0.870588235294 0.811764705882 0.764705882353 1.0"/>
    </material>
    <material name="red">
        <color rgba="0.80078125 0.12890625 0.1328125 1.0"/>
    </material>
    <material name="white">
        <color rgba="1.0 1.0 1.0 1.0"/>
    </material>
    <!-- <gazebo reference="base_link">
        <material>Gazebo/Orange</material>
    </gazebo> -->
    <gazebo reference="link_chassis">
        <material>Gazebo/Orange</material>
    </gazebo>
    <gazebo reference="link_left_wheel">
        <material>Gazebo/Blue</material>
    </gazebo>
    <gazebo reference="link_right_wheel">
        <material>Gazebo/Blue</material>
    </gazebo>
    <!-- <gazebo>
        <plugin name="differential_drive_controller" filename="libgazebo_ros_diff_drive.so">
            <alwaysOn>true</alwaysOn>
            <updateRate>50.0</updateRate>
            <leftJoint>car_base_front_left_wheel</leftJoint>
            <rightJoint>car_base_front_right_wheel</rightJoint>
            <wheelSeparation>1.0</wheelSeparation>
            <wheelDiameter>0.5</wheelDiameter>
            <torque>1.0</torque>
            <commandTopic>cmd_vel</commandTopic>
            <odometryTopic>odom</odometryTopic>
            <odometryFrame>odom</odometryFrame>
            <robotBaseFrame>base_link</robotBaseFrame>
            <publishWheelTF>true</publishWheelTF>
            <publishWheelJointState>true</publishWheelJointState>
            <legecyMode>false</legecyMode>
            <wheelAcceleration>1</wheelAcceleration>
        </plugin>
    </gazebo> -->
    <gazebo reference="camera_link">
    <material>Gazebo/Green</material>
    <sensor type="camera" name="camera1">
      <update_rate>30.0</update_rate>
      <camera name="head">
        <horizontal_fov>1.3962634</horizontal_fov>
        <image>
          <width>800</width>
          <height>800</height>
          <format>R8G8B8</format>
        </image>
        <clip>
          <near>0.02</near>
          <far>300</far>
        </clip>
      </camera>
      <plugin name="camera_controller" filename="libgazebo_ros_camera.so">
        <alwaysOn>true</alwaysOn>
        <updateRate>0.0</updateRate>
        <cameraName>my_robot/camera1</cameraName>
        <imageTopicName>image_raw</imageTopicName>
        <cameraInfoTopicName>camera_info</cameraInfoTopicName>
        <frameName>camera</frameName>
        <hackBaseline>0.07</hackBaseline>
        <distortionK1>0.0</distortionK1>
        <distortionK2>0.0</distortionK2>
        <distortionK3>0.0</distortionK3>
        <distortionT1>0.0</distortionT1>
        <distortionT2>0.0</distortionT2>
      </plugin>
    </sensor>
  </gazebo>

    <link name="base_link">
        <visual>
            <geometry>
                <box size =".001 .001 .001"/>
            </geometry>
            <origin rpy="0 0 0" xyz="0 0 0"/>
        </visual>
    </link>
    <!-- <joint name="base_link_car" type="fixed">
        <origin xyz="0.0 0.0 0.0" rpy="0.0 0.0 0.0"/>
        <parent link="base_link"/>
        <child link="link_chassis"/>
    </joint> -->

    <link name="link_chassis">
        <!-- pose and inertial -->
        <pose>0 0 1 0 0 0</pose>
        <inertial>
            <mass value="15.0"/>
            <origin xyz="0.0 0 0.1" rpy=" 0 0 0"/>
            <inertia ixx="0.12" ixy="0" ixz="0" iyy="0.1" iyz="0" izz="0.1" />
        </inertial>

        <collision name="collision_chassis">
            <geometry>
                <box size="1 0.8 0.4"/>
            </geometry>
        </collision>

        <visual>
            <origin rpy="0 0 0" xyz="0 0 0.0"/>
            <geometry>
                <box size="1 0.8 0.4"/>
            </geometry>
            <material name="blue"/>
        </visual>

        <collision name='caster_front_collision'>
            <origin xyz="-0.5 0 -0.3" rpy=" 0 0 0"/>
            <geometry>
                <sphere radius="0.1"/>
            </geometry>
            <surface>
                <friction>
                    <ode>
                        <mu>0</mu>
                        <mu2>0</mu2>
                        <slip1>1.0</slip1>
                        <slip2>1.0</slip2>
                    </ode>
                </friction>
            </surface>
        </collision>

        <visual name='caster_front_visual'>
            <origin xyz="-0.5 0 -0.3" rpy=" 0 0 0"/>
            <geometry>
                <sphere radius="0.1"/>
            </geometry>
        </visual>

    </link>
    <!--   Joint for chassis  -->
    <joint name="joint_chassis" type="continuous">
        <origin rpy="0 0 0" xyz="0 0 0.4"/>
        <child link="link_chassis" />
        <parent link="base_link"/>
        <axis rpy="0 0 0" xyz="0 1 0"/>
        <limit effort="10000" velocity="1000"/>
        <joint_properties damping="1.0" friction="1.0" />
    </joint> 

    <!-- Create camera link -->
    <link name = "camera_link">
        <inertial>
            <mass value="5" />
            <origin xyz="0 0 0" rpy="0 0 0"/>
            <box_inertia m="5" x="0.05" y="0.05" z="0.05" />
            <inertia ixx="1e-6" ixy="0" ixz="0" iyy="1e-6" iyz="0" izz="1e-6" />
        </inertial>
        <collision name="collision_camera">
            <geometry>
                <box size="0.05 0.05 0.05"/>
            </geometry>
        </collision>
        <visual>
            <origin rpy="0 0 0" xyz="0 0 0.0"/>
            <geometry>
                <box size="0.05 0.05 0.05"/>
            </geometry>
            <material name="white"/>
        </visual>
    </link>
    <joint name = "joint_camera" type = "continuous">
        <origin rpy="0 0 0" xyz="0.5 0 0.3"/>
        <child link="camera_link" />
        <parent link="link_chassis"/>
        <axis rpy="0 0 0" xyz="0 1 0"/>
        <limit effort="10000" velocity="1000"/>
        <joint_properties damping="1.0" friction="1.0" />
    </joint>

    <!-- Create wheel right -->
    <link name="link_right_wheel">
         <inertial>
            <origin xyz="0 0 0" rpy="0 1.5707 1.5707"/>
            <mass value="5"/>
            <inertia ixx=".1" ixy="0.0" ixz="0.0" iyy=".1" iyz="0.0" izz=".1"/>
        </inertial>

        <collision name="link_right_wheel_collision">
            <origin rpy="0 1.5707 1.5707" xyz="0 0 0" />
            <geometry>
                <cylinder length="0.3" radius="0.25"/>
            </geometry>
        </collision>

        <visual name="link_right_wheel_visual">
            <origin rpy="0 1.5707 1.5707" xyz="0 0 0"/>
            <geometry>
                <cylinder length="0.3" radius="0.25"/>
            </geometry>
        </visual>
    </link>

    <!--   Joint for right wheel  -->
    <joint name="joint_right_wheel" type="continuous">
        <origin rpy="0 0 0" xyz="0.333838 -0.6 -0.15"/>
        <child link="link_right_wheel" />
        <parent link="link_chassis"/>
        <axis xyz="0 1 0" rpy="0 0 0"/>
        <limit effort="10000" velocity="1000"/>
        <joint_properties damping="1.0" friction="1.0"/>
    </joint>


    <!-- Left Wheel link -->
    <link name="link_left_wheel">
         <inertial>
            <origin xyz="0 0 0" rpy="0 1.5707 1.5707"/>
            <mass value="5"/>
            <inertia ixx=".1" ixy="0.0" ixz="0.0" iyy=".1" iyz="0.0" izz=".1"/>
        </inertial>

        <collision name="link_left_wheel_collision">
            <origin rpy="0 1.5707 1.5707" xyz="0 0 0" />
            <geometry>
                <cylinder length="0.3" radius="0.25"/>
            </geometry>
        </collision>

        <visual name="link_left_wheel_visual">
            <origin rpy="0 1.5707 1.5707" xyz="0 0 0"/>
            <geometry>
                <cylinder length="0.3" radius="0.25"/>
            </geometry>
        </visual>

    </link>

    <!--   Joint for right wheel  -->
    <joint name="joint_left_wheel" type="continuous">
        <origin rpy="0 0 0" xyz="0.333838 0.6 -0.15"/>
        <child link="link_left_wheel" />
        <parent link="link_chassis"/>
        <axis xyz="0 1 0" rpy="0 0 0"/>
        <limit effort="10000" velocity="1000"/>
        <joint_properties damping="1.0" friction="1.0"/>
    </joint>

</robot>
